Workbook

Sheet README
A1: Atlante delle scene di movimento: foglio di raccolta v0
A3: A cosa serve
A4: Raccogliere, da fonti pubbliche, quanto è presente ogni disciplina in ogni città (community, scuole, spazi, eventi, competizioni, atleti, interesse online, scala di progressione) e confrontarlo con la presenza Red Bull. La presenza Red Bull è UN dato tra gli altri, non il centro.
A6: Come si usa
A7: 1. Disciplines e Cities: elenchi di partenza, da confermare. Si possono aggiungere righe.
A8: 2. Signals: una riga per ogni misura (città x disciplina x segnale). Si scrive SEMPRE il valore grezzo, l'unità, la fonte e la data; il punteggio 0-5 e la confidenza (H/M/L) servono per il confronto.
A9: 3. Events, Athletes, Ladder, Keywords: tabelle di dettaglio. RedBull: inventario delle tappe Red Bull trovate.
A10: 4. Grid si calcola da sola dalle altre schede (formule): non va modificata a mano.
A11: 5. Decisions: registro delle scelte e delle domande aperte.
A13: Regole
A14: Solo fonti pubbliche. Nessun dato personale di privati: in Athletes solo professionisti o partecipanti a gare con risultati pubblicati, nessun contatto o profilo social.
A15: Ogni numero è una stima con un intervallo e una confidenza; un numero senza fonte non entra.
... A23: Colori: intestazioni blu scuro; celle azzurre = formule (non toccare); riga grigia = esempio.

Sheet Disciplines
A1: disc_id | B1: family (level 1) | C1: discipline (level 2) | D1: sub-style (level 3) | E1: pilot (Y/N/Proposed) | F1: adjacent (Y/N) | G1: red_bull_reference (Y/N/?) | H1: notes
A2: URB-BRK | B2: Urban / street | C2: Breaking | E2: Y | F2: N | G2: Y | H2: Reference: Red Bull BC One
A3: URB-HIP | B3: Urban / street | C3: Hip hop | E3: Y | F3: N | G3: Y | H3: Reference: Red Bull Dance Your Style (mixed street styles)
A4: URB-MIX | B4: Urban / street | C4: Mixed-style street dance | D4: all-style | E4: N | F4: N | G4: Y | H4: Format label used by Dance Your Style; not a style of its own
A5: URB-HOU | B5: Urban / street | C5: House | E5: N | F5: N | G5: ?
A6: URB-POP | B6: Urban / street | C6: Popping | E6: N | F6: N | G6: ?
A7: URB-LOC | B7: Urban / street | C7: Locking | E7: N | F7: N | G7: ?
A8: URB-KRU | B8: Urban / street | C8: Krump | E8: N | F8: N | G8: ?
A9: CAR-SAL | B9: Latin / Caribbean | C9: Salsa | D9: all sub-styles | E9: Y | F9: N | G9: ? | H9: Pilot discipline; sub-styles below
A10: CAR-SAL-CUB | B10: Latin / Caribbean | C10: Salsa | D10: Cuban (casino) | E10: N | F10: N | G10: ? | H10: Record only where the city scene differs
A11: CAR-SAL-LA | B11: Latin / Caribbean | C11: Salsa | D11: LA style | E11: N | F11: N | G11: ?
A12: CAR-SAL-NY | B12: Latin / Caribbean | C12: Salsa | D12: New York (on2) | E12: N | F12: N | G12: ?
A13: CAR-SAL-PR | B13: Latin / Caribbean | C13: Salsa | D13: Puerto Rican | E13: N | F13: N | G13: ?
A14: CAR-BCH | B14: Latin / Caribbean | C14: Bachata | D14: all sub-styles | E14: Y | F14: N | G14: ? | H14: Pilot discipline
A15: CAR-BCH-DOM | B15: Latin / Caribbean | C15: Bachata | D15: Dominican | E15: N | F15: N | G15: ?
A16: CAR-BCH-SEN | B16: Latin / Caribbean | C16: Bachata | D16: Sensual / moderna | E16: N | F16: N | G16: ?
A17: CAR-MER | B17: Latin / Caribbean | C17: Merengue | E17: N | F17: N | G17: ?
A18: CAR-DHL | B18: Latin / Caribbean | C18: Dancehall | E18: N | F18: N | G18: ? | H18: Jamaican; family to be confirmed
A19: AFR-KIZ | B19: Afro-Latin | C19: Kizomba | E19: N | F19: N | G19: ? | H19: Family to be confirmed
A20: ACR-TRK | B20: Acrobatic / show-off | C20: Tricking | E20: Proposed | F20: Y | G20: ? | H20: Third pilot discipline proposed; example event: Hooked (Amsterdam)
A21: ACR-AER | B21: Acrobatic / show-off | C21: Aerial | E21: N | F21: Y | G21: ?
A22: ACR-POL | B22: Acrobatic / show-off | C22: Pole | E22: N | F22: Y | G22: ?
A23: BAL-STD | B23: Ballroom / dancesport | C23: Standard | E23: N | F23: N | G23: ?
A24: BAL-LAT | B24: Ballroom / dancesport | C24: Latin dancesport | E24: N | F24: N | G24: ? | H24: Competition format; different scene from social Latin
A25: CON-CON | B25: Contemporary / classical | C25: Contemporary | E25: N | F25: N | G25: ?
A26: CON-BAL | B26: Contemporary / classical | C26: Ballet | E26: N | F26: N | G26: ?

Sheet Cities
A1: city_id | B1: city | C1: country | D1: status (core/reserve/anchor) | E1: size_tier_estimate (S/M/L/XL) | F1: population (fill) | G1: population_source | H1: lat | I1: lon | J1: why_included | K1: notes
A2: SBG | B2: Salzburg | C2: Austria | D2: core | E2: S | H2: 47.8 | I2: 13.04 | J2: Home city, small; Dance Your Style qualifier 2026 | K2: Ground truth: checkable on site
A3: INN | B3: Innsbruck | C3: Austria | D3: core | E3: S | H3: 47.27 | I3: 11.39 | J3: Small; BC One cypher 2026
A4: VIE | B4: Vienna | C4: Austria | D4: core | E4: L | H4: 48.21 | I4: 16.37 | J4: Large; Dance Your Style national final 2026
A5: MUC | B5: Munich | C5: Germany | D5: core | E5: L | H5: 48.14 | I5: 11.58 | J5: Large, German-speaking; Red Bull footprint to check
A6: MIL | B6: Milan | C6: Italy | D6: core | E6: L | H6: 45.46 | I6: 9.19 | J6: Large, Italian scene; Red Bull footprint to check
A7: BCN | B7: Barcelona | C7: Spain | D7: core | E7: L | H7: 41.39 | I7: 2.17 | J7: Large; strong Latin scene expected (to verify); Red Bull footprint to check
A8: AMS | B8: Amsterdam | C8: Netherlands | D8: core | E8: M | H8: 52.37 | I8: 4.9 | J8: Medium; Hooked tricking tournament | K8: Rotterdam (BC One cypher 2026) is nearby
A9: BER | B9: Berlin | C9: Germany | D9: core | E9: XL | H9: 52.52 | I9: 13.4 | J9: Very large; BC One cypher 2026
A10: GRZ | B10: Graz | C10: Austria | D10: reserve | E10: M | H10: 47.07 | I10: 15.44 | J10: Medium Austrian city
A11: MAD | B11: Madrid | C11: Spain | D11: reserve | E11: XL | H11: 40.42 | I11: -3.7 | J11: Very large; BC One cypher 2026
A12: PAR | B12: Paris | C12: France | D12: reserve | E12: XL | H12: 48.86 | I12: 2.35 | J12: Very large; BC One cypher 2026 in Aubervilliers (Paris area) | K12: Metro-area handling to decide
A13: NYC | B13: New York | C13: USA | D13: anchor | E13: XL | H13: 40.71 | I13: -74.01 | J13: Benchmark for hip hop and New York style salsa; not comparable with Europe | K13: Anchor: proposal
A14: CLO | B14: Cali | C14: Colombia | D14: anchor | E14: L | H14: 3.45 | I14: -76.53 | J14: Benchmark for salsa; not comparable with Europe | K14: Anchor: proposal

Sheet SignalDefs
A1: signal_id | B1: signal | C1: definition | D1: unit | E1: score guide | F1: typical public sources
A2: COM | B2: Community | C2: How large and active the practising community is (groups, crews, clubs, online communities) | D2: count + estimated size range | E2: 0-5 relative to city size tier | F2: Meetup, public group pages, club registries, local associations
A3: SCH | B3: Schools and classes | C3: Number of schools/teachers and weekly class slots | D3: schools; classes per week | E3: 0-5 relative to city size tier | F3: School websites and timetables, Google Maps listings
A4: SPA | B4: Spaces and venues | C4: Availability of rehearsal/teaching space and clubs hosting socials | D4: venues; rental price per hour (EUR) | E4: 0-5; record prices in notes | F4: Studio rental pages, venue sites
A5: EVT | B5: Events | C5: Regular socials, jams, festivals, shows per year | D5: events per year | E5: 0-5 relative to city size tier | F5: Event calendars, ticket platforms, organiser pages
A6: CMP | B6: Competitions | C6: Battles/contests per year and their level | D6: competitions per year; highest level | E6: 0-5 | F6: Federation and organiser calendars, published results
A7: ATH | B7: Athletes | C7: Publicly listed competitors and professionals from the city | D7: count from public results | E7: 0-5 | F7: Published results, federation rankings (aggregate counts only)
A8: ONL | B8: Online interest | C8: Search and social interest in the discipline for this geography | D8: relative index 0-100 | E8: 0-5 | F8: Google Trends, public video and hashtag counts
A9: LAD | B9: Ladder completeness | C9: Rungs present: class, social/jam, local battle, national comp, international comp | D9: rungs present (0-5) | E9: score equals rungs present | F9: Ladder sheet
A10: PRC | B10: Prices | C10: Typical drop-in class price and studio rental price | D10: EUR | E10: no score (context only) | F10: School websites, studio rental pages

Sheet Signals
A1: row_id | B1: city_id | C1: disc_id | D1: signal_id | E1: raw_value | F1: unit | G1: score_0_5 | H1: confidence (H/M/L) | I1: source_url | J1: date_accessed | K1: notes
A2: EXAMPLE | B2: EXAMPLE | C2: URB-HIP | D2: SCH | E2: format only: e.g. 5 | F2: schools | G2: 3 | H2: L | I2: https://example.org (replace) | J2: 2026-10-19 | K2: Delete this row before use

Sheet Events
A1: event_id | B1: name | C1: city | D1: country | E1: disc_id | F1: type | G1: edition / year | H1: frequency | I1: scale (public figure) | J1: red_bull_involved | K1: source_url | L1: date_accessed | M1: notes
A2: EV-001 | B2: Hooked Tournament | C2: Amsterdam | D2: Netherlands | E2: ACR-TRK | F2: battle + workshops | G2: 2025 (10th edition, 19-21 Dec) | H2: annual | I2: visitors from 50+ countries (no headcount given) | J2: not stated on the page | K2: https://hookedtournament.com/ | L2: 2026-10-19 | M2: Site does not mention Red Bull. Organiser not named on the page. Sponsors listed: City of Amsterdam, Bergtoys, Airtrack Sale, The Inhumans Agency

Sheet RedBull
A1: rb_id | B1: series | C1: level | D1: city | E1: country | F1: date_2026 | G1: venue | H1: disc_id | I1: city_certainty | J1: source_url | K1: date_accessed | L1: notes
A2: RB-001 | B2: BC One | C2: cypher | D2: Madrid | E2: Spain | F2: 2026-03-15 | H2: URB-BRK | I2: stated | J2: https://www.redbull.com/int-en/event-series/red-bull-bc-one | K2: 2026-10-19
A3: RB-002 | B3: BC One | C3: cypher | D3: Berlin | E3: Germany | F3: 2026-03-28 | H3: URB-BRK | I3: stated | J3: https://www.redbull.com/int-en/event-series/red-bull-bc-one | K3: 2026-10-19
A4: RB-003 | B4: BC One | C4: cypher | D4: Rotterdam | E4: Netherlands | F4: 2026-03-29 | H4: URB-BRK | I4: stated | J4: https://www.redbull.com/int-en/event-series/red-bull-bc-one | K4: 2026-10-19
A5: RB-004 | B5: BC One | C5: cypher | D5: London | E5: UK | F5: 2026-04-11 | H5: URB-BRK | I5: stated | J5: https://www.redbull.com/int-en/event-series/red-bull-bc-one | K5: 2026-10-19
A6: RB-005 | B6: BC One | C6: cypher | D6: Lausanne | E6: Switzerland | F6: 2026-04-18 | G6: Palais de Beaulieu | H6: URB-BRK | I6: stated | J6: https://www.redbull.com/int-en/event-series/red-bull-bc-one | K6: 2026-10-19
A7: RB-006 | B7: BC One | C7: cypher | D7: Innsbruck | E7: Austria | F7: 2026-04-19 | G7: Villa Blanka | H7: URB-BRK | I7: stated | J7: https://www.redbull.com/int-en/event-series/red-bull-bc-one | K7: 2026-10-19
A8: RB-007 | B8: BC One | C8: cypher | D8: Ghent | E8: Belgium | F8: 2026-04-26 | G8: Wintercircus | H8: URB-BRK | I8: inferred from venue | J8: https://www.redbull.com/int-en/event-series/red-bull-bc-one | K8: 2026-10-19 | L8: Page names only Belgium; verify city
A9: RB-008 | B9: BC One | C9: cypher | D9: Kyiv | E9: Ukraine | F9: 2026-05-09 | G9: VDNH | H9: URB-BRK | I9: inferred from venue | J9: https://www.redbull.com/int-en/event-series/red-bull-bc-one | K9: 2026-10-19 | L9: Page names only Ukraine; verify city
A10: RB-009 | B10: BC One | C10: cypher | D10: Bucharest | E10: Romania | F10: 2026-05-22 | G10: ParkLake Mall | H10: URB-BRK | I10: inferred from venue | J10: https://www.redbull.com/int-en/event-series/red-bull-bc-one | K10: 2026-10-19 | L10: Page names only Romania; verify city
A11: RB-010 | B11: BC One | C11: cypher | D11: L'Aquila | E11: Italy | F11: 2026-05-22 | H11: URB-BRK | I11: stated | J11: https://www.redbull.com/int-en/event-series/red-bull-bc-one | K11: 2026-10-19
A12: RB-011 | B12: BC One | C12: cypher | D12: Aubervilliers | E12: France | F12: 2026-09-12 | G12: Le Point Fort | H12: URB-BRK | I12: stated | J12: https://www.redbull.com/int-en/event-series/red-bull-bc-one | K12: 2026-10-19 | L12: Paris metro area
A13: RB-012 | B13: BC One | C13: world final | D13: Toronto | E13: Canada | F13: 2026-11-29 | H13: URB-BRK | I13: stated | J13: https://www.redbull.com/int-en/event-series/red-bull-bc-one | K13: 2026-10-19 | L13: Upcoming
A14: RB-013 | B14: BC One | C14: cypher / national | D14: Almaty | E14: Kazakhstan | F14: 2026-02-28 | H14: URB-BRK | I14: stated | J14: https://www.redbull.com/int-en/event-series/red-bull-bc-one | K14: 2026-10-19
A15: RB-014 | B15: BC One | C15: cypher / national | D15: Denver | E15: USA | F15: 2026-04-03 | G15: Boettcher Concert Hall | H15: URB-BRK | I15: stated | J15: https://www.redbull.com/int-en/event-series/red-bull-bc-one | K15: 2026-10-19
A16: RB-015 | B16: BC One | C16: cypher / national | D16: Seattle | E16: USA | F16: 2026-05-31 | G16: Showbox SoDo | H16: URB-BRK | I16: stated | J16: https://www.redbull.com/int-en/event-series/red-bull-bc-one | K16: 2026-10-19
A17: RB-016 | B17: BC One | C17: cypher / national | D17: Detroit | E17: USA | F17: 2026-06-05 | G17: MCSDA | H17: URB-BRK | I17: stated | J17: https://www.redbull.com/int-en/event-series/red-bull-bc-one | K17: 2026-10-19
A18: RB-017 | B18: BC One | C18: cypher / national | E18: USA | F18: 2026-08-22 | G18: Port Pavilion, Broadway Pier | H18: URB-BRK | I18: country only | J18: https://www.redbull.com/int-en/event-series/red-bull-bc-one | K18: 2026-10-19
A19: RB-018 | B19: BC One | C19: cypher / national | E19: India | F19: 2026-06-05 | G19: Pinhole Studio | H19: URB-BRK | I19: country only | J19: https://www.redbull.com/int-en/event-series/red-bull-bc-one | K19: 2026-10-19
A20: RB-019 | B20: BC One | C20: cypher / national | D20: Taipei | E20: Taiwan | F20: 2026-06-06 | H20: URB-BRK | I20: stated | J20: https://www.redbull.com/int-en/event-series/red-bull-bc-one | K20: 2026-10-19
A21: RB-020 | B21: BC One | C21: cypher / national | D21: Medellin | E21: Colombia | F21: 2026-07-12 | H21: URB-BRK | I21: stated | J21: https://www.redbull.com/int-en/event-series/red-bull-bc-one | K21: 2026-10-19
A22: RB-021 | B22: BC One | C22: cypher / national | E22: Thailand | F22: 2026-07-18 | G22: HOSTBKK Arts Center | H22: URB-BRK | I22: country only | J22: https://www.redbull.com/int-en/event-series/red-bull-bc-one | K22: 2026-10-19
A23: RB-022 | B23: BC One | C23: cypher / national | E23: Japan | F23: 2026-08-23 | G23: Meijo University campus, Nagoya area | H23: URB-BRK | I23: country only | J23: https://www.redbull.com/int-en/event-series/red-bull-bc-one | K23: 2026-10-19
A24: RB-023 | B24: BC One | C24: cypher / national | E24: Canada | F24: 2026-08-29 | H24: URB-BRK | I24: country only | J24: https://www.redbull.com/int-en/event-series/red-bull-bc-one | K24: 2026-10-19
A25: RB-024 | B25: BC One | C25: cypher / national | E25: South Africa | F25: 2026-09-05 | G25: Thibault Square Plaza | H25: URB-BRK | I25: country only | J25: https://www.redbull.com/int-en/event-series/red-bull-bc-one | K25: 2026-10-19
A26: RB-025 | B26: BC One | C26: cypher / national | E26: Australia | F26: 2026-09-26 | G26: Street University | H26: URB-BRK | I26: country only | J26: https://www.redbull.com/int-en/event-series/red-bull-bc-one | K26: 2026-10-19
A27: RB-026 | B27: BC One | C27: cypher / national | E27: Morocco | F27: 2026-09-26 | H27: URB-BRK | I27: country only | J27: https://www.redbull.com/int-en/event-series/red-bull-bc-one | K27: 2026-10-19
A28: RB-027 | B28: Dance Your Style | C28: world final | D28: Zurich | E28: Switzerland | F28: 2026-10-24 | G28: Hallenstadion | H28: URB-MIX | I28: stated | J28: https://www.redbull.com/int-en/event-series/red-bull-dance-your-style | K28: 2026-10-19 | L28: Upcoming; date from series page
A29: RB-028 | B29: Dance Your Style | C29: national final | D29: London | E29: UK | F29: 2026-05-30 | H29: URB-MIX | I29: stated | J29: https://www.redbull.com/int-en/event-series/red-bull-dance-your-style | K29: 2026-10-19 | L29: Qualifiers across the UK
A30: RB-029 | B30: Dance Your Style | C30: national final | D30: Basel | E30: Switzerland | F30: unclear (page shows 16 May - 4 Jul) | H30: URB-MIX | I30: stated | J30: https://www.redbull.com/int-en/event-series/red-bull-dance-your-style | K30: 2026-10-19 | L30: First-time Weekender on 4 Jul; dates ambiguous
A31: RB-030 | B31: Dance Your Style | C31: national final | D31: Hamburg | E31: Germany | F31: 2026-08-02 | G31: Inselpark Arena | H31: URB-MIX | I31: stated | J31: https://www.redbull.com/int-en/event-series/red-bull-dance-your-style | K31: 2026-10-19
A32: RB-031 | B32: Dance Your Style | C32: national final | D32: Vienna | E32: Austria | F32: 2026-08-28 | G32: Gloriette, Schoenbrunn | H32: URB-MIX | I32: stated | J32: https://www.redbull.com/int-en/event-series/red-bull-dance-your-style ; https://www.vienna.at/red-bull-dance-your-style-2026-national-final-for-the-first-time-at-the-gloriette-in-vienna/10240406 | K32: 2026-10-19 | L32: 16 dancers; first time at this venue
A33: RB-032 | B33: Dance Your Style | C33: qualifier | D33: Salzburg | E33: Austria | F33: 2026-07-04 | G33: Domquartier | H33: URB-MIX | I33: stated | J33: https://www.vienna.at/red-bull-dance-your-style-2026-national-final-for-the-first-time-at-the-gloriette-in-vienna/10240406 | K33: 2026-10-19 | L33: Last 4 of 16 places awarded here
A34: RB-033 | B34: Dance Your Style | C34: tour stop | D34: Vienna | E34: Austria | F34: 2026-06-28 to 2026-07-04 (range) | H34: URB-MIX | I34: stated | J34: https://www.vienna.at/red-bull-dance-your-style-2026-national-final-for-the-first-time-at-the-gloriette-in-vienna/10240406 | K34: 2026-10-19 | L34: Article says tour stops 'including' Salzburg, Vienna, Red Bull Ring; other stops may exist
A35: RB-034 | B35: Dance Your Style | C35: tour stop | D35: Spielberg (Red Bull Ring) | E35: Austria | F35: 2026-06-28 to 2026-07-04 (range) | G35: Red Bull Ring | H35: URB-MIX | I35: stated | J35: https://www.vienna.at/red-bull-dance-your-style-2026-national-final-for-the-first-time-at-the-gloriette-in-vienna/10240406 | K35: 2026-10-19 | L35: Same range as above; exact date not stated
A36: RB-035 | B36: Dance Your Style | C36: final | D36: Helsinki | E36: Finland | F36: 2026-09-05 | G36: Senaatintori | H36: URB-MIX | I36: stated | J36: https://www.redbull.com/int-en/event-series/red-bull-dance-your-style | K36: 2026-10-19 | L36: Finnish final also lists Oulu
A37: RB-036 | B37: Dance Your Style | C37: final | D37: Oulu | E37: Finland | F37: 2026-09-05 | H37: URB-MIX | I37: stated | J37: https://www.redbull.com/int-en/event-series/red-bull-dance-your-style | K37: 2026-10-19 | L37: Listed together with Helsinki
A38: RB-037 | B38: Dance Your Style | C38: final | D38: Montpellier | E38: France | F38: 2026-09-23 to 2026-09-26 | H38: URB-MIX | I38: stated | J38: https://www.redbull.com/int-en/event-series/red-bull-dance-your-style | K38: 2026-10-19 | L38: Free qualifier tickets and pre-selection mentioned
A39: RB-038 | B39: Dance Your Style | C39: national final | D39: Lisbon | E39: Portugal | F39: 2026-09-05 | G39: MAAT Central | H39: URB-MIX | I39: inferred from venue | J39: https://www.redbull.com/int-en/event-series/red-bull-dance-your-style | K39: 2026-10-19 | L39: Page describes this as a past edition; year to verify
A40: RB-039 | B40: Dance Your Style | C40: national final | E40: Philippines | F40: 2026-01-16 to 2026-04-11 | G40: Bridgetowne Concert Grounds | H40: URB-MIX | I40: country only | J40: https://www.redbull.com/int-en/event-series/red-bull-dance-your-style | K40: 2026-10-19
...

Sheet Ladder
A1: city_id | B1: disc_id | C1: rung | D1: present (Y/N/?) | E1: example | F1: source_url | G1: notes
A2: EXAMPLE | B2: URB-HIP | C2: 1 class | D2: ? | E2: format only | G2: Delete before use; rungs: 1 class, 2 social/jam, 3 local battle or show, 4 national competition, 5 international competition

Sheet Athletes
A1: ath_id | B1: public_name | C1: disc_id | D1: base_city_id | E1: country | F1: level | G1: red_bull_athlete (Y/N/?) | H1: source_url | I1: date_accessed | J1: notes
A2: EXAMPLE | B2: format only | C2: URB-HIP | D2: SBG | E2: Austria | F2: national | G2: ? | H2: https://example.org | I2: 2026-10-19 | J2: Delete before use. Only publicly listed competitors and professionals; no private individuals, no contacts, no social profiles

Sheet Keywords
A1: kw_id | B1: disc_id | C1: language | D1: keyword | E1: ambiguity_note | F1: source_tool | G1: geo | H1: period | I1: relative_index (fill) | J1: date_accessed
A2: KW-001 | B2: URB-BRK | C2: EN | D2: breakdance | F2: Google Trends
A3: KW-002 | B3: URB-BRK | C3: DE | D3: breakdance | F3: Google Trends
A4: KW-003 | B4: URB-BRK | C4: IT | D4: breakdance | F4: Google Trends
A5: KW-004 | B5: URB-BRK | C5: ES | D5: breakdance | F5: Google Trends
A6: KW-005 | B6: URB-BRK | C6: EN | D6: bboy | F6: Google Trends
A7: KW-006 | B7: URB-BRK | C7: EN | D7: red bull bc one | F7: Google Trends
A8: KW-007 | B8: URB-HIP | C8: EN | D8: hip hop dance | E8: May mix music and dance interest; compare with the dance-specific term | F8: Google Trends
A9: KW-008 | B9: URB-HIP | C9: DE | D9: hip hop tanzen | E9: May mix music and dance interest; compare with the dance-specific term | F9: Google Trends
A10: KW-009 | B10: URB-HIP | C10: IT | D10: corso hip hop | E10: May mix music and dance interest; compare with the dance-specific term | F10: Google Trends
A11: KW-010 | B11: URB-HIP | C11: ES | D11: clases de hip hop | E11: May mix music and dance interest; compare with the dance-specific term | F11: Google Trends
A12: KW-011 | B12: CAR-SAL | C12: EN | D12: salsa dancing | E12: 'salsa' alone also means the sauce; always pair with a dance/class word | F12: Google Trends
A13: KW-012 | B13: CAR-SAL | C13: DE | D13: salsa tanzen | E13: 'salsa' alone also means the sauce; always pair with a dance/class word | F13: Google Trends
A14: KW-013 | B14: CAR-SAL | C14: IT | D14: corso di salsa | E14: 'salsa' alone also means the sauce; always pair with a dance/class word | F14: Google Trends
A15: KW-014 | B15: CAR-SAL | C15: ES | D15: clases de salsa | E15: 'salsa' alone also means the sauce; always pair with a dance/class word | F15: Google Trends
A16: KW-015 | B16: CAR-BCH | C16: EN | D16: bachata class | F16: Google Trends
A17: KW-016 | B17: CAR-BCH | C17: DE | D17: bachata tanzen | F17: Google Trends
A18: KW-017 | B18: CAR-BCH | C18: IT | D18: corso di bachata | F18: Google Trends
A19: KW-018 | B19: CAR-BCH | C19: ES | D19: clases de bachata | F19: Google Trends
A20: KW-019 | B20: ACR-TRK | C20: EN | D20: tricking | E20: Check for other meanings of the word | F20: Google Trends
A21: KW-020 | B21: ACR-TRK | C21: EN | D21: tricking battle | E21: Check for other meanings of the word | F21: Google Trends

Sheet Grid
A1: Grid: formulas from Signals and RedBull. Do not edit.
A2: Block 1: average score (0-5) per city and discipline. Block 2: number of signal rows filled. Block 3: Red Bull events listed for the city name (exact match).
A4: Block 1: average score
A5: city_id | B5: city | C5: URB-BRK | D5: URB-HIP | E5: CAR-SAL | F5: CAR-BCH | G5: ACR-TRK
A6: =Cities!A2 -> SBG | B6: =Cities!B2 -> Salzburg | C6: =IFERROR(AVERAGEIFS(Signals!$G:$G,Signals!$B:$B,$A6,Signals!$C:$C,C$5),"") | D6: =IFERROR(AVERAGEIFS(Signals!$G:$G,Signals!$B:$B,$A6,Signals!$C:$C,D$5),"") | E6: =IFERROR(AVERAGEIFS(Signals!$G:$G,Signals!$B:$B,$A6,Signals!$C:$C,E$5),"") | F6: =IFERROR(AVERAGEIFS(Signals!$G:$G,Signals!$B:$B,$A6,Signals!$C:$C,F$5),"") | G6: =IFERROR(AVERAGEIFS(Signals!$G:$G,Signals!$B:$B,$A6,Signals!$C:$C,G$5),"")
A7: =Cities!A3 -> INN | B7: =Cities!B3 -> Innsbruck | C7: =IFERROR(AVERAGEIFS(Signals!$G:$G,Signals!$B:$B,$A7,Signals!$C:$C,C$5),"") | D7: =IFERROR(AVERAGEIFS(Signals!$G:$G,Signals!$B:$B,$A7,Signals!$C:$C,D$5),"") | E7: =IFERROR(AVERAGEIFS(Signals!$G:$G,Signals!$B:$B,$A7,Signals!$C:$C,E$5),"") | F7: =IFERROR(AVERAGEIFS(Signals!$G:$G,Signals!$B:$B,$A7,Signals!$C:$C,F$5),"") | G7: =IFERROR(AVERAGEIFS(Signals!$G:$G,Signals!$B:$B,$A7,Signals!$C:$C,G$5),"")
A8: =Cities!A4 -> VIE | B8: =Cities!B4 -> Vienna | C8: =IFERROR(AVERAGEIFS(Signals!$G:$G,Signals!$B:$B,$A8,Signals!$C:$C,C$5),"") | D8: =IFERROR(AVERAGEIFS(Signals!$G:$G,Signals!$B:$B,$A8,Signals!$C:$C,D$5),"") | E8: =IFERROR(AVERAGEIFS(Signals!$G:$G,Signals!$B:$B,$A8,Signals!$C:$C,E$5),"") | F8: =IFERROR(AVERAGEIFS(Signals!$G:$G,Signals!$B:$B,$A8,Signals!$C:$C,F$5),"") | G8: =IFERROR(AVERAGEIFS(Signals!$G:$G,Signals!$B:$B,$A8,Signals!$C:$C,G$5),"")
A9: =Cities!A5 -> MUC | B9: =Cities!B5 -> Munich | C9: =IFERROR(AVERAGEIFS(Signals!$G:$G,Signals!$B:$B,$A9,Signals!$C:$C,C$5),"") | D9: =IFERROR(AVERAGEIFS(Signals!$G:$G,Signals!$B:$B,$A9,Signals!$C:$C,D$5),"") | E9: =IFERROR(AVERAGEIFS(Signals!$G:$G,Signals!$B:$B,$A9,Signals!$C:$C,E$5),"") | F9: =IFERROR(AVERAGEIFS(Signals!$G:$G,Signals!$B:$B,$A9,Signals!$C:$C,F$5),"") | G9: =IFERROR(AVERAGEIFS(Signals!$G:$G,Signals!$B:$B,$A9,Signals!$C:$C,G$5),"")
A10: =Cities!A6 -> MIL | B10: =Cities!B6 -> Milan | C10: =IFERROR(AVERAGEIFS(Signals!$G:$G,Signals!$B:$B,$A10,Signals!$C:$C,C$5),"") | D10: =IFERROR(AVERAGEIFS(Signals!$G:$G,Signals!$B:$B,$A10,Signals!$C:$C,D$5),"") | E10: =IFERROR(AVERAGEIFS(Signals!$G:$G,Signals!$B:$B,$A10,Signals!$C:$C,E$5),"") | F10: =IFERROR(AVERAGEIFS(Signals!$G:$G,Signals!$B:$B,$A10,Signals!$C:$C,F$5),"") | G10: =IFERROR(AVERAGEIFS(Signals!$G:$G,Signals!$B:$B,$A10,Signals!$C:$C,G$5),"")
A11: =Cities!A7 -> BCN | B11: =Cities!B7 -> Barcelona | C11: =IFERROR(AVERAGEIFS(Signals!$G:$G,Signals!$B:$B,$A11,Signals!$C:$C,C$5),"") | D11: =IFERROR(AVERAGEIFS(Signals!$G:$G,Signals!$B:$B,$A11,Signals!$C:$C,D$5),"") | E11: =IFERROR(AVERAGEIFS(Signals!$G:$G,Signals!$B:$B,$A11,Signals!$C:$C,E$5),"") | F11: =IFERROR(AVERAGEIFS(Signals!$G:$G,Signals!$B:$B,$A11,Signals!$C:$C,F$5),"") | G11: =IFERROR(AVERAGEIFS(Signals!$G:$G,Signals!$B:$B,$A11,Signals!$C:$C,G$5),"")
A12: =Cities!A8 -> AMS | B12: =Cities!B8 -> Amsterdam | C12: =IFERROR(AVERAGEIFS(Signals!$G:$G,Signals!$B:$B,$A12,Signals!$C:$C,C$5),"") | D12: =IFERROR(AVERAGEIFS(Signals!$G:$G,Signals!$B:$B,$A12,Signals!$C:$C,D$5),"") | E12: =IFERROR(AVERAGEIFS(Signals!$G:$G,Signals!$B:$B,$A12,Signals!$C:$C,E$5),"") | F12: =IFERROR(AVERAGEIFS(Signals!$G:$G,Signals!$B:$B,$A12,Signals!$C:$C,F$5),"") | G12: =IFERROR(AVERAGEIFS(Signals!$G:$G,Signals!$B:$B,$A12,Signals!$C:$C,G$5),"")
A13: =Cities!A9 -> BER | B13: =Cities!B9 -> Berlin | C13: =IFERROR(AVERAGEIFS(Signals!$G:$G,Signals!$B:$B,$A13,Signals!$C:$C,C$5),"") | D13: =IFERROR(AVERAGEIFS(Signals!$G:$G,Signals!$B:$B,$A13,Signals!$C:$C,D$5),"") | E13: =IFERROR(AVERAGEIFS(Signals!$G:$G,Signals!$B:$B,$A13,Signals!$C:$C,E$5),"") | F13: =IFERROR(AVERAGEIFS(Signals!$G:$G,Signals!$B:$B,$A13,Signals!$C:$C,F$5),"") | G13: =IFERROR(AVERAGEIFS(Signals!$G:$G,Signals!$B:$B,$A13,Signals!$C:$C,G$5),"")
A14: =Cities!A10 -> GRZ | B14: =Cities!B10 -> Graz | C14: =IFERROR(AVERAGEIFS(Signals!$G:$G,Signals!$B:$B,$A14,Signals!$C:$C,C$5),"") | D14: =IFERROR(AVERAGEIFS(Signals!$G:$G,Signals!$B:$B,$A14,Signals!$C:$C,D$5),"") | E14: =IFERROR(AVERAGEIFS(Signals!$G:$G,Signals!$B:$B,$A14,Signals!$C:$C,E$5),"") | F14: =IFERROR(AVERAGEIFS(Signals!$G:$G,Signals!$B:$B,$A14,Signals!$C:$C,F$5),"") | G14: =IFERROR(AVERAGEIFS(Signals!$G:$G,Signals!$B:$B,$A14,Signals!$C:$C,G$5),"")
A15: =Cities!A11 -> MAD | B15: =Cities!B11 -> Madrid | C15: =IFERROR(AVERAGEIFS(Signals!$G:$G,Signals!$B:$B,$A15,Signals!$C:$C,C$5),"") | D15: =IFERROR(AVERAGEIFS(Signals!$G:$G,Signals!$B:$B,$A15,Signals!$C:$C,D$5),"") | E15: =IFERROR(AVERAGEIFS(Signals!$G:$G,Signals!$B:$B,$A15,Signals!$C:$C,E$5),"") | F15: =IFERROR(AVERAGEIFS(Signals!$G:$G,Signals!$B:$B,$A15,Signals!$C:$C,F$5),"") | G15: =IFERROR(AVERAGEIFS(Signals!$G:$G,Signals!$B:$B,$A15,Signals!$C:$C,G$5),"")
A16: =Cities!A12 -> PAR | B16: =Cities!B12 -> Paris | C16: =IFERROR(AVERAGEIFS(Signals!$G:$G,Signals!$B:$B,$A16,Signals!$C:$C,C$5),"") | D16: =IFERROR(AVERAGEIFS(Signals!$G:$G,Signals!$B:$B,$A16,Signals!$C:$C,D$5),"") | E16: =IFERROR(AVERAGEIFS(Signals!$G:$G,Signals!$B:$B,$A16,Signals!$C:$C,E$5),"") | F16: =IFERROR(AVERAGEIFS(Signals!$G:$G,Signals!$B:$B,$A16,Signals!$C:$C,F$5),"") | G16: =IFERROR(AVERAGEIFS(Signals!$G:$G,Signals!$B:$B,$A16,Signals!$C:$C,G$5),"")
A17: =Cities!A13 -> NYC | B17: =Cities!B13 -> New York | C17: =IFERROR(AVERAGEIFS(Signals!$G:$G,Signals!$B:$B,$A17,Signals!$C:$C,C$5),"") | D17: =IFERROR(AVERAGEIFS(Signals!$G:$G,Signals!$B:$B,$A17,Signals!$C:$C,D$5),"") | E17: =IFERROR(AVERAGEIFS(Signals!$G:$G,Signals!$B:$B,$A17,Signals!$C:$C,E$5),"") | F17: =IFERROR(AVERAGEIFS(Signals!$G:$G,Signals!$B:$B,$A17,Signals!$C:$C,F$5),"") | G17: =IFERROR(AVERAGEIFS(Signals!$G:$G,Signals!$B:$B,$A17,Signals!$C:$C,G$5),"")
A18: =Cities!A14 -> CLO | B18: =Cities!B14 -> Cali | C18: =IFERROR(AVERAGEIFS(Signals!$G:$G,Signals!$B:$B,$A18,Signals!$C:$C,C$5),"") | D18: =IFERROR(AVERAGEIFS(Signals!$G:$G,Signals!$B:$B,$A18,Signals!$C:$C,D$5),"") | E18: =IFERROR(AVERAGEIFS(Signals!$G:$G,Signals!$B:$B,$A18,Signals!$C:$C,E$5),"") | F18: =IFERROR(AVERAGEIFS(Signals!$G:$G,Signals!$B:$B,$A18,Signals!$C:$C,F$5),"") | G18: =IFERROR(AVERAGEIFS(Signals!$G:$G,Signals!$B:$B,$A18,Signals!$C:$C,G$5),"")
A20: Block 2: signal rows filled
A21: city_id | B21: city | C21: URB-BRK | D21: URB-HIP | E21: CAR-SAL | F21: CAR-BCH | G21: ACR-TRK
A22: =Cities!A2 -> SBG | B22: =Cities!B2 -> Salzburg | C22: =COUNTIFS(Signals!$B:$B,$A22,Signals!$C:$C,C$21) -> 0 | D22: =COUNTIFS(Signals!$B:$B,$A22,Signals!$C:$C,D$21) -> 0 | E22: =COUNTIFS(Signals!$B:$B,$A22,Signals!$C:$C,E$21) -> 0 | F22: =COUNTIFS(Signals!$B:$B,$A22,Signals!$C:$C,F$21) -> 0 | G22: =COUNTIFS(Signals!$B:$B,$A22,Signals!$C:$C,G$21) -> 0
A23: =Cities!A3 -> INN | B23: =Cities!B3 -> Innsbruck | C23: =COUNTIFS(Signals!$B:$B,$A23,Signals!$C:$C,C$21) -> 0 | D23: =COUNTIFS(Signals!$B:$B,$A23,Signals!$C:$C,D$21) -> 0 | E23: =COUNTIFS(Signals!$B:$B,$A23,Signals!$C:$C,E$21) -> 0 | F23: =COUNTIFS(Signals!$B:$B,$A23,Signals!$C:$C,F$21) -> 0 | G23: =COUNTIFS(Signals!$B:$B,$A23,Signals!$C:$C,G$21) -> 0
A24: =Cities!A4 -> VIE | B24: =Cities!B4 -> Vienna | C24: =COUNTIFS(Signals!$B:$B,$A24,Signals!$C:$C,C$21) -> 0 | D24: =COUNTIFS(Signals!$B:$B,$A24,Signals!$C:$C,D$21) -> 0 | E24: =COUNTIFS(Signals!$B:$B,$A24,Signals!$C:$C,E$21) -> 0 | F24: =COUNTIFS(Signals!$B:$B,$A24,Signals!$C:$C,F$21) -> 0 | G24: =COUNTIFS(Signals!$B:$B,$A24,Signals!$C:$C,G$21) -> 0
A25: =Cities!A5 -> MUC | B25: =Cities!B5 -> Munich | C25: =COUNTIFS(Signals!$B:$B,$A25,Signals!$C:$C,C$21) -> 0 | D25: =COUNTIFS(Signals!$B:$B,$A25,Signals!$C:$C,D$21) -> 0 | E25: =COUNTIFS(Signals!$B:$B,$A25,Signals!$C:$C,E$21) -> 0 | F25: =COUNTIFS(Signals!$B:$B,$A25,Signals!$C:$C,F$21) -> 0 | G25: =COUNTIFS(Signals!$B:$B,$A25,Signals!$C:$C,G$21) -> 0
A26: =Cities!A6 -> MIL | B26: =Cities!B6 -> Milan | C26: =COUNTIFS(Signals!$B:$B,$A26,Signals!$C:$C,C$21) -> 0 | D26: =COUNTIFS(Signals!$B:$B,$A26,Signals!$C:$C,D$21) -> 0 | E26: =COUNTIFS(Signals!$B:$B,$A26,Signals!$C:$C,E$21) -> 0 | F26: =COUNTIFS(Signals!$B:$B,$A26,Signals!$C:$C,F$21) -> 0 | G26: =COUNTIFS(Signals!$B:$B,$A26,Signals!$C:$C,G$21) -> 0
A27: =Cities!A7 -> BCN | B27: =Cities!B7 -> Barcelona | C27: =COUNTIFS(Signals!$B:$B,$A27,Signals!$C:$C,C$21) -> 0 | D27: =COUNTIFS(Signals!$B:$B,$A27,Signals!$C:$C,D$21) -> 0 | E27: =COUNTIFS(Signals!$B:$B,$A27,Signals!$C:$C,E$21) -> 0 | F27: =COUNTIFS(Signals!$B:$B,$A27,Signals!$C:$C,F$21) -> 0 | G27: =COUNTIFS(Signals!$B:$B,$A27,Signals!$C:$C,G$21) -> 0
A28: =Cities!A8 -> AMS | B28: =Cities!B8 -> Amsterdam | C28: =COUNTIFS(Signals!$B:$B,$A28,Signals!$C:$C,C$21) -> 0 | D28: =COUNTIFS(Signals!$B:$B,$A28,Signals!$C:$C,D$21) -> 0 | E28: =COUNTIFS(Signals!$B:$B,$A28,Signals!$C:$C,E$21) -> 0 | F28: =COUNTIFS(Signals!$B:$B,$A28,Signals!$C:$C,F$21) -> 0 | G28: =COUNTIFS(Signals!$B:$B,$A28,Signals!$C:$C,G$21) -> 0
A29: =Cities!A9 -> BER | B29: =Cities!B9 -> Berlin | C29: =COUNTIFS(Signals!$B:$B,$A29,Signals!$C:$C,C$21) -> 0 | D29: =COUNTIFS(Signals!$B:$B,$A29,Signals!$C:$C,D$21) -> 0 | E29: =COUNTIFS(Signals!$B:$B,$A29,Signals!$C:$C,E$21) -> 0 | F29: =COUNTIFS(Signals!$B:$B,$A29,Signals!$C:$C,F$21) -> 0 | G29: =COUNTIFS(Signals!$B:$B,$A29,Signals!$C:$C,G$21) -> 0
A30: =Cities!A10 -> GRZ | B30: =Cities!B10 -> Graz | C30: =COUNTIFS(Signals!$B:$B,$A30,Signals!$C:$C,C$21) -> 0 | D30: =COUNTIFS(Signals!$B:$B,$A30,Signals!$C:$C,D$21) -> 0 | E30: =COUNTIFS(Signals!$B:$B,$A30,Signals!$C:$C,E$21) -> 0 | F30: =COUNTIFS(Signals!$B:$B,$A30,Signals!$C:$C,F$21) -> 0 | G30: =COUNTIFS(Signals!$B:$B,$A30,Signals!$C:$C,G$21) -> 0
A31: =Cities!A11 -> MAD | B31: =Cities!B11 -> Madrid | C31: =COUNTIFS(Signals!$B:$B,$A31,Signals!$C:$C,C$21) -> 0 | D31: =COUNTIFS(Signals!$B:$B,$A31,Signals!$C:$C,D$21) -> 0 | E31: =COUNTIFS(Signals!$B:$B,$A31,Signals!$C:$C,E$21) -> 0 | F31: =COUNTIFS(Signals!$B:$B,$A31,Signals!$C:$C,F$21) -> 0 | G31: =COUNTIFS(Signals!$B:$B,$A31,Signals!$C:$C,G$21) -> 0
A32: =Cities!A12 -> PAR | B32: =Cities!B12 -> Paris | C32: =COUNTIFS(Signals!$B:$B,$A32,Signals!$C:$C,C$21) -> 0 | D32: =COUNTIFS(Signals!$B:$B,$A32,Signals!$C:$C,D$21) -> 0 | E32: =COUNTIFS(Signals!$B:$B,$A32,Signals!$C:$C,E$21) -> 0 | F32: =COUNTIFS(Signals!$B:$B,$A32,Signals!$C:$C,F$21) -> 0 | G32: =COUNTIFS(Signals!$B:$B,$A32,Signals!$C:$C,G$21) -> 0
A33: =Cities!A13 -> NYC | B33: =Cities!B13 -> New York | C33: =COUNTIFS(Signals!$B:$B,$A33,Signals!$C:$C,C$21) -> 0 | D33: =COUNTIFS(Signals!$B:$B,$A33,Signals!$C:$C,D$21) -> 0 | E33: =COUNTIFS(Signals!$B:$B,$A33,Signals!$C:$C,E$21) -> 0 | F33: =COUNTIFS(Signals!$B:$B,$A33,Signals!$C:$C,F$21) -> 0 | G33: =COUNTIFS(Signals!$B:$B,$A33,Signals!$C:$C,G$21) -> 0
A34: =Cities!A14 -> CLO | B34: =Cities!B14 -> Cali | C34: =COUNTIFS(Signals!$B:$B,$A34,Signals!$C:$C,C$21) -> 0 | D34: =COUNTIFS(Signals!$B:$B,$A34,Signals!$C:$C,D$21) -> 0 | E34: =COUNTIFS(Signals!$B:$B,$A34,Signals!$C:$C,E$21) -> 0 | F34: =COUNTIFS(Signals!$B:$B,$A34,Signals!$C:$C,F$21) -> 0 | G34: =COUNTIFS(Signals!$B:$B,$A34,Signals!$C:$C,G$21) -> 0
A36: Block 3: Red Bull events listed (2026, exact city name)
A37: city_id | B37: city | C37: Red Bull events listed | D37: URB-HIP | E37: CAR-SAL | F37: CAR-BCH | G37: ACR-TRK
A38: =Cities!A2 -> SBG | B38: =Cities!B2 -> Salzburg | C38: =COUNTIFS(RedBull!$D:$D,$B38) -> 1
A39: =Cities!A3 -> INN | B39: =Cities!B3 -> Innsbruck | C39: =COUNTIFS(RedBull!$D:$D,$B39) -> 1
A40: =Cities!A4 -> VIE | B40: =Cities!B4 -> Vienna | C40: =COUNTIFS(RedBull!$D:$D,$B40) -> 2
A41: =Cities!A5 -> MUC | B41: =Cities!B5 -> Munich | C41: =COUNTIFS(RedBull!$D:$D,$B41) -> 0
A42: =Cities!A6 -> MIL | B42: =Cities!B6 -> Milan | C42: =COUNTIFS(RedBull!$D:$D,$B42) -> 0
A43: =Cities!A7 -> BCN | B43: =Cities!B7 -> Barcelona | C43: =COUNTIFS(RedBull!$D:$D,$B43) -> 0
...

Sheet Decisions
A1: date | B1: decision / question | C1: status | D1: notes
A2: 2026-10-19 | B2: Scope: dance, with show-off/acrobatic disciplines as 'adjacent'. The data model does not depend on dance, so other sports can be added later | C2: decided
A3: 2026-10-19 | B3: Core question: where are the scenes, how strong are they, and what potential exists where Red Bull is absent or partial. Red Bull presence is one input, not the centre | C3: decided
A4: 2026-10-19 | B4: Sources: public only. A Red Bull contact validates and completes after enough data is collected | C4: decided
A5: 2026-10-19 | B5: Pilot disciplines: hip hop family (Red Bull reference), Caribbean/Latin dance, plus one more | C5: decided | D5: Third discipline: tricking proposed, to confirm
A6: 2026-10-19 | B6: Cities: Europe as the comparable core; at most 2-3 anchor cities outside Europe as benchmarks only | C6: proposed | D6: Confirm list in Cities
A7: 2026-10-19 | B7: Ladder of progression (class, social, local battle, national, international) is tested inside this workbook, not as a separate tool; keep it only if data is easy to get | C7: decided
A8: 2026-10-19 | B8: Under/over-served is a secondary reading computed from the same data | C8: decided
A9: 2026-10-19 | B9: Interactive map that can be shared: decide the tool after the first dataset exists | C9: open | D9: Options: free map tools or a published page
A10: 2026-10-19 | B10: Column headers are in English so the file can be shared with Red Bull contacts | C10: proposed | D10: Easy to change
A11: 2026-10-19 | B11: Open: Dance Your Style World Final is on 2026-10-24 in Zurich (per Red Bull series page): worth attending to observe a major event? | C11: open
